
20190827145921 - urllib3.connectionpool -DEBUG - D:\python\lib\site-packages\urllib3\connectionpool.py - Starting new HTTP connection (1): www.baidu.com
20190827145921 - urllib3.connectionpool -DEBUG - D:\python\lib\site-packages\urllib3\connectionpool.py - http://www.baidu.com:80 "GET / HTTP/1.1" 200 None
20190827145921 - root -INFO - H:/pycharm_Project/gpcloud.git/Day17/01.requests_get.py - www.baidu.com check successfuly,status_code is 200
20190827145921 - urllib3.connectionpool -DEBUG - D:\python\lib\site-packages\urllib3\connectionpool.py - Starting new HTTP connection (1): www.43s99s.com
20190827145922 - root -ERROR - H:/pycharm_Project/gpcloud.git/Day17/01.requests_get.py - HTTPConnectionPool(host='www.43s99s.com', port=80): Max retries exceeded with url: / (Caused by NewConnectionError('<urllib3.connection.HTTPConnection object at 0x00000257537484A8>: Failed to establish a new connection: [Errno 11001] getaddrinfo failed'))
20190827145922 - urllib3.connectionpool -DEBUG - D:\python\lib\site-packages\urllib3\connectionpool.py - Starting new HTTP connection (1): www.alisysun.com
20190827145922 - root -ERROR - H:/pycharm_Project/gpcloud.git/Day17/01.requests_get.py - HTTPConnectionPool(host='www.alisysun.com', port=80): Max retries exceeded with url: / (Caused by NewConnectionError('<urllib3.connection.HTTPConnection object at 0x0000025753748400>: Failed to establish a new connection: [Errno 11001] getaddrinfo failed'))
20190827145922 - urllib3.connectionpool -DEBUG - D:\python\lib\site-packages\urllib3\connectionpool.py - Starting new HTTP connection (1): www.douban.com
20190827145922 - urllib3.connectionpool -DEBUG - D:\python\lib\site-packages\urllib3\connectionpool.py - http://www.douban.com:80 "GET / HTTP/1.1" 301 162
20190827145922 - urllib3.connectionpool -DEBUG - D:\python\lib\site-packages\urllib3\connectionpool.py - Starting new HTTPS connection (1): www.douban.com
20190827145923 - root -ERROR - H:/pycharm_Project/gpcloud.git/Day17/01.requests_get.py - HTTPSConnectionPool(host='www.douban.com', port=443): Max retries exceeded with url: / (Caused by ConnectTimeoutError(<urllib3.connection.VerifiedHTTPSConnection object at 0x0000025753748AC8>, 'Connection to www.douban.com timed out. (connect timeout=0.3)'))
20190827145923 - urllib3.connectionpool -DEBUG - D:\python\lib\site-packages\urllib3\connectionpool.py - Starting new HTTP connection (1): news.baidu.com
20190827145923 - urllib3.connectionpool -DEBUG - D:\python\lib\site-packages\urllib3\connectionpool.py - http://news.baidu.com:80 "GET / HTTP/1.1" 200 None
20190827145923 - root -INFO - H:/pycharm_Project/gpcloud.git/Day17/01.requests_get.py - news.baidu.com check successfuly,status_code is 200
20190827150210 - urllib3.connectionpool -DEBUG - D:\python\lib\site-packages\urllib3\connectionpool.py - Starting new HTTP connection (1): www.baidu.com
20190827150210 - urllib3.connectionpool -DEBUG - D:\python\lib\site-packages\urllib3\connectionpool.py - http://www.baidu.com:80 "GET / HTTP/1.1" 200 None
20190827150210 - root -INFO - H:/pycharm_Project/gpcloud.git/Day17/01.requests_get.py - www.baidu.com check successfuly,status_code is 200
20190827150210 - urllib3.connectionpool -DEBUG - D:\python\lib\site-packages\urllib3\connectionpool.py - Starting new HTTP connection (1): www.43s99.com
20190827150210 - urllib3.connectionpool -DEBUG - D:\python\lib\site-packages\urllib3\connectionpool.py - http://www.43s99.com:80 "GET / HTTP/1.1" 301 162
20190827150210 - urllib3.connectionpool -DEBUG - D:\python\lib\site-packages\urllib3\connectionpool.py - Starting new HTTPS connection (1): www.43s99.com
20190827150211 - urllib3.connectionpool -DEBUG - D:\python\lib\site-packages\urllib3\connectionpool.py - https://www.43s99.com:443 "GET / HTTP/1.1" 502 150
20190827150211 - root -ERROR - H:/pycharm_Project/gpcloud.git/Day17/01.requests_get.py - www.43s99.com check failed, status_code: 502, timeout None
20190827150211 - urllib3.connectionpool -DEBUG - D:\python\lib\site-packages\urllib3\connectionpool.py - Starting new HTTP connection (1): www.alisysun.com
20190827150211 - root -ERROR - H:/pycharm_Project/gpcloud.git/Day17/01.requests_get.py - HTTPConnectionPool(host='www.alisysun.com', port=80): Max retries exceeded with url: / (Caused by NewConnectionError('<urllib3.connection.HTTPConnection object at 0x0000019348117240>: Failed to establish a new connection: [Errno 11001] getaddrinfo failed'))
20190827150211 - urllib3.connectionpool -DEBUG - D:\python\lib\site-packages\urllib3\connectionpool.py - Starting new HTTP connection (1): www.douban.com
20190827150211 - urllib3.connectionpool -DEBUG - D:\python\lib\site-packages\urllib3\connectionpool.py - http://www.douban.com:80 "GET / HTTP/1.1" 301 162
20190827150211 - urllib3.connectionpool -DEBUG - D:\python\lib\site-packages\urllib3\connectionpool.py - Starting new HTTPS connection (1): www.douban.com
20190827150211 - urllib3.connectionpool -DEBUG - D:\python\lib\site-packages\urllib3\connectionpool.py - https://www.douban.com:443 "GET / HTTP/1.1" 200 None
20190827150211 - root -INFO - H:/pycharm_Project/gpcloud.git/Day17/01.requests_get.py - www.douban.com check successfuly,status_code is 200
20190827150211 - urllib3.connectionpool -DEBUG - D:\python\lib\site-packages\urllib3\connectionpool.py - Starting new HTTP connection (1): news.baidu.com
20190827150212 - urllib3.connectionpool -DEBUG - D:\python\lib\site-packages\urllib3\connectionpool.py - http://news.baidu.com:80 "GET / HTTP/1.1" 200 None
20190827150212 - root -INFO - H:/pycharm_Project/gpcloud.git/Day17/01.requests_get.py - news.baidu.com check successfuly,status_code is 200
